<sdf version='1.7'>
  <world name='default'>
    <light name='sun' type='directional'>
      <cast_shadows>1</cast_shadows>
      <pose>0 0 10 0 -0 0</pose>
      <diffuse>0.8 0.8 0.8 1</diffuse>
      <specular>0.2 0.2 0.2 1</specular>
      <attenuation>
        <range>1000</range>
        <constant>0.9</constant>
        <linear>0.01</linear>
        <quadratic>0.001</quadratic>
      </attenuation>
      <direction>-0.5 0.1 -0.9</direction>
      <spot>
        <inner_angle>0</inner_angle>
        <outer_angle>0</outer_angle>
        <falloff>0</falloff>
      </spot>
    </light>
    <model name='ground_plane'>
      <static>1</static>
      <link name='link'>
        <collision name='collision'>
          <geometry>
            <plane>
              <normal>0 0 1</normal>
              <size>100 100</size>
            </plane>
          </geometry>
          <surface>
            <friction>
              <ode>
                <mu>100</mu>
                <mu2>50</mu2>
              </ode>
              <torsional>
                <ode/>
              </torsional>
            </friction>
            <contact>
              <ode/>
            </contact>
            <bounce/>
          </surface>
          <max_contacts>10</max_contacts>
        </collision>
        <visual name='visual'>
          <cast_shadows>0</cast_shadows>
          <geometry>
            <plane>
              <normal>0 0 1</normal>
              <size>100 100</size>
            </plane>
          </geometry>
          <material>
            <script>
              <uri>file://media/materials/scripts/gazebo.material</uri>
              <name>Gazebo/Grey</name>
            </script>
          </material>
        </visual>
        <self_collide>0</self_collide>
        <enable_wind>0</enable_wind>
        <kinematic>0</kinematic>
      </link>
    </model>
    <gravity>0 0 -9.8</gravity>
    <magnetic_field>6e-06 2.3e-05 -4.2e-05</magnetic_field>
    <atmosphere type='adiabatic'/>
    <physics type='ode'>
      <max_step_size>0.001</max_step_size>
      <real_time_factor>1</real_time_factor>
      <real_time_update_rate>1000</real_time_update_rate>
    </physics>
    <scene>
      <ambient>0.4 0.4 0.4 1</ambient>
      <background>0.7 0.7 0.7 1</background>
      <shadows>1</shadows>
    </scene>
    <wind/>
    <spherical_coordinates>
      <surface_model>EARTH_WGS84</surface_model>
      <latitude_deg>0</latitude_deg>
      <longitude_deg>0</longitude_deg>
      <elevation>0</elevation>
      <heading_deg>0</heading_deg>
    </spherical_coordinates>
    <state world_name='default'>
      <sim_time>73 342000000</sim_time>
      <real_time>0 0</real_time>
      <wall_time>1624386930 880322967</wall_time>
      <iterations>0</iterations>
      <model name='ground_plane'>
        <pose>0 0 0 0 -0 0</pose>
        <scale>1 1 1</scale>
        <link name='link'>
          <pose>0 0 0 0 -0 0</pose>
          <velocity>0 0 0 0 -0 0</velocity>
          <acceleration>0 0 0 0 -0 0</acceleration>
          <wrench>0 0 0 0 -0 0</wrench>
        </link>
      </model>
      <model name='trial0'>
        <pose>0 0 -1 0 -0 0</pose>
        <scale>1 1 1</scale>
        <link name='wam/base_link'>
          <pose>0 0 0 0 -0 0</pose>
          <velocity>0 0 0 0 -0 0</velocity>
          <acceleration>0 0 0 0 -0 0</acceleration>
          <wrench>0 0 0 0 -0 0</wrench>
        </link>
        <link name='wam/bhand/finger_1/dist_link'>
          <pose>-0.025 -0.119939 1.3344 1.5708 -0.785398 -1.5708</pose>
          <velocity>0 0 0 0 -0 0</velocity>
          <acceleration>0 0 0 0 -0 0</acceleration>
          <wrench>0 0 0 0 -0 0</wrench>
        </link>
        <link name='wam/bhand/finger_1/med_link'>
          <pose>-0.025 -0.049999 1.3314 1.5708 0 -1.5708</pose>
          <velocity>0 0 0 0 -0 0</velocity>
          <acceleration>0 0 0 0 -0 0</acceleration>
          <wrench>0 0 0 0 -0 0</wrench>
        </link>
        <link name='wam/bhand/finger_1/prox_link'>
          <pose>-0.025 1e-06 1.2975 -0 -0 -1.5708</pose>
          <velocity>0 0 0 0 -0 0</velocity>
          <acceleration>0 0 0 0 -0 0</acceleration>
          <wrench>0 0 0 0 -0 0</wrench>
        </link>
        <link name='wam/bhand/finger_2/dist_link'>
          <pose>0.025 -0.119939 1.3344 1.5708 -0.785398 -1.5708</pose>
          <velocity>0 0 0 0 -0 0</velocity>
          <acceleration>0 0 0 0 -0 0</acceleration>
          <wrench>0 0 0 0 -0 0</wrench>
        </link>
        <link name='wam/bhand/finger_2/med_link'>
          <pose>0.025 -0.049999 1.3314 1.5708 0 -1.5708</pose>
          <velocity>0 0 0 0 -0 0</velocity>
          <acceleration>0 0 0 0 -0 0</acceleration>
          <wrench>0 0 0 0 -0 0</wrench>
        </link>
        <link name='wam/bhand/finger_2/prox_link'>
          <pose>0.025 1e-06 1.2975 -0 -0 -1.5708</pose>
          <velocity>0 0 0 0 -0 0</velocity>
          <acceleration>0 0 0 0 -0 0</acceleration>
          <wrench>0 0 0 0 -0 0</wrench>
        </link>
        <link name='wam/bhand/finger_3/dist_link'>
          <pose>-0 0.119941 1.3344 1.5708 -0.785398 1.5708</pose>
          <velocity>0 0 0 0 -0 0</velocity>
          <acceleration>0 0 0 0 -0 0</acceleration>
          <wrench>0 0 0 0 -0 0</wrench>
        </link>
        <link name='wam/bhand/finger_3/med_link'>
          <pose>0 0.050001 1.3314 1.5708 -0 1.5708</pose>
          <velocity>0 0 0 0 -0 0</velocity>
          <acceleration>0 0 0 0 -0 0</acceleration>
          <wrench>0 0 0 0 -0 0</wrench>
        </link>
        <link name='wam/forearm_link'>
          <pose>0.045 0 0.896 -1.5708 0 0</pose>
          <velocity>0 0 0 0 -0 0</velocity>
          <acceleration>0 0 0 0 -0 0</acceleration>
          <wrench>0 0 0 0 -0 0</wrench>
        </link>
        <link name='wam/shoulder_pitch_link'>
          <pose>0 0 0.346 -1.5708 0 0</pose>
          <velocity>0 0 0 0 -0 0</velocity>
          <acceleration>0 0 0 0 -0 0</acceleration>
          <wrench>0 0 0 0 -0 0</wrench>
        </link>
        <link name='wam/shoulder_yaw_link'>
          <pose>0 0 0.346 0 -0 0</pose>
          <velocity>0 0 0 0 -0 0</velocity>
          <acceleration>0 0 0 0 -0 0</acceleration>
          <wrench>0 0 0 0 -0 0</wrench>
        </link>
        <link name='wam/upper_arm_link'>
          <pose>0 0 0.346 0 -0 0</pose>
          <velocity>0 0 0 0 -0 0</velocity>
          <acceleration>0 0 0 0 -0 0</acceleration>
          <wrench>0 0 0 0 -0 0</wrench>
        </link>
        <link name='wam/wrist_palm_link'>
          <pose>0 1e-06 1.196 0 -0 0</pose>
          <velocity>0 0 0 0 -0 0</velocity>
          <acceleration>0 0 0 0 -0 0</acceleration>
          <wrench>0 0 0 0 -0 0</wrench>
        </link>
        <link name='wam/wrist_pitch_link'>
          <pose>0 1e-06 1.196 -1.5708 0 0</pose>
          <velocity>0 0 0 0 -0 0</velocity>
          <acceleration>0 0 0 0 -0 0</acceleration>
          <wrench>0 0 0 0 -0 0</wrench>
        </link>
        <link name='wam/wrist_yaw_link'>
          <pose>0 1e-06 1.196 0 -0 0</pose>
          <velocity>0 0 0 0 -0 0</velocity>
          <acceleration>0 0 0 0 -0 0</acceleration>
          <wrench>0 0 0 0 -0 0</wrench>
        </link>
      </model>
      <light name='sun'>
        <pose>0 0 10 0 -0 0</pose>
      </light>
    </state>
    <gui fullscreen='0'>
      <camera name='user_camera'>
        <pose>5 -5 2 0 0.275643 2.35619</pose>
        <view_controller>orbit</view_controller>
        <projection_type>perspective</projection_type>
      </camera>
    </gui>
    <model name='trial0'>
      <joint name='wam/wam_fixed_joint' type='fixed'>
        <pose relative_to='__model__'>0 0 1 0 -0 0</pose>
        <parent>world</parent>
        <child>wam/base_link</child>
      </joint>
      <link name='wam/base_link'>
        <pose relative_to='wam/wam_fixed_joint'>0 0 0 0 -0 0</pose>
        <inertial>
          <pose>0 0 0 0 -0 0</pose>
          <mass>1</mass>
          <inertia>
            <ixx>0.1</ixx>
            <ixy>0</ixy>
            <ixz>0</ixz>
            <iyy>0.1</iyy>
            <iyz>0</iyz>
            <izz>0.1</izz>
          </inertia>
        </inertial>
        <collision name='wam/base_link_collision'>
          <pose>0 0 0 0 -0 0</pose>
          <geometry>
            <mesh>
              <scale>1 1 1</scale>
              <uri>/home/nckmlb/nuws/src/barrett_ros_arms_test/barrett_model/models/sw_meshes/base_link_convex.dae</uri>
            </mesh>
          </geometry>
          <surface>
            <contact>
              <ode/>
            </contact>
            <bounce/>
            <friction>
              <torsional>
                <ode/>
              </torsional>
              <ode/>
            </friction>
          </surface>
          <max_contacts>10</max_contacts>
        </collision>
        <visual name='wam/base_link_visual'>
          <pose>0 0 0 0 -0 0</pose>
          <geometry>
            <mesh>
              <scale>1 1 1</scale>
              <uri>/home/nckmlb/nuws/src/barrett_ros_arms_test/barrett_model/models/sw_meshes/base_link_fine.stl</uri>
            </mesh>
          </geometry>
        </visual>
        <self_collide>0</self_collide>
        <enable_wind>0</enable_wind>
        <kinematic>0</kinematic>
      </link>
      <joint name='wam/base_yaw_joint' type='revolute'>
        <pose relative_to='wam/base_link'>0 0 0.346 0 -0 0</pose>
        <parent>wam/base_link</parent>
        <child>wam/shoulder_yaw_link</child>
        <axis>
          <xyz>0 0 1</xyz>
          <limit>
            <lower>-2.6</lower>
            <upper>2.6</upper>
            <effort>60</effort>
            <velocity>2</velocity>
          </limit>
          <dynamics>
            <damping>1.98</damping>
            <friction>0</friction>
            <spring_reference>0</spring_reference>
            <spring_stiffness>0</spring_stiffness>
          </dynamics>
        </axis>
        <physics>
          <provide_feedback>1</provide_feedback>
          <ode>
            <implicit_spring_damper>1</implicit_spring_damper>
            <cfm_damping>1</cfm_damping>
            <limit>
              <cfm>0</cfm>
              <erp>0.2</erp>
            </limit>
            <provide_feedback>1</provide_feedback>
          </ode>
        </physics>
      </joint>
      <link name='wam/shoulder_yaw_link'>
        <pose relative_to='wam/base_yaw_joint'>0 0 0 0 -0 0</pose>
        <inertial>
          <pose>-0.004434 -0.000665 -0.128904 0 -0 0</pose>
          <mass>5</mass>
          <inertia>
            <ixx>0.13488</ixx>
            <ixy>-0.00012485</ixy>
            <ixz>0.00213041</ixz>
            <iyy>0.0904633</iyy>
            <iyz>-0.00068555</iyz>
            <izz>0.113284</izz>
          </inertia>
        </inertial>
        <collision name='wam/shoulder_yaw_link_collision'>
          <pose>0 0 0 0 -0 0</pose>
          <geometry>
            <mesh>
              <scale>1 1 1</scale>
              <uri>/home/nckmlb/nuws/src/barrett_ros_arms_test/barrett_model/models/sw_meshes/shoulder_link_convex_decomposition.dae</uri>
            </mesh>
          </geometry>
          <surface>
            <contact>
              <ode/>
            </contact>
            <bounce/>
            <friction>
              <torsional>
                <ode/>
              </torsional>
              <ode/>
            </friction>
          </surface>
          <max_contacts>10</max_contacts>
        </collision>
        <visual name='wam/shoulder_yaw_link_visual'>
          <pose>0 0 0 0 -0 0</pose>
          <geometry>
            <mesh>
              <scale>1 1 1</scale>
              <uri>/home/nckmlb/nuws/src/barrett_ros_arms_test/barrett_model/models/sw_meshes/shoulder_link_fine.stl</uri>
            </mesh>
          </geometry>
        </visual>
        <self_collide>0</self_collide>
        <enable_wind>0</enable_wind>
        <kinematic>0</kinematic>
      </link>
      <joint name='wam/shoulder_pitch_joint' type='revolute'>
        <pose relative_to='wam/shoulder_yaw_link'>0 0 0 -1.5708 0 0</pose>
        <parent>wam/shoulder_yaw_link</parent>
        <child>wam/shoulder_pitch_link</child>
        <axis>
          <xyz>0 0 1</xyz>
          <limit>
            <lower>-1.985</lower>
            <upper>1.985</upper>
            <effort>60</effort>
            <velocity>2</velocity>
          </limit>
          <dynamics>
            <damping>0.55</damping>
            <friction>0</friction>
            <spring_reference>0</spring_reference>
            <spring_stiffness>0</spring_stiffness>
          </dynamics>
        </axis>
        <physics>
          <provide_feedback>1</provide_feedback>
          <ode>
            <implicit_spring_damper>1</implicit_spring_damper>
            <cfm_damping>1</cfm_damping>
            <limit>
              <cfm>0</cfm>
              <erp>0.2</erp>
            </limit>
            <provide_feedback>1</provide_feedback>
          </ode>
        </physics>
      </joint>
      <link name='wam/shoulder_pitch_link'>
        <pose relative_to='wam/shoulder_pitch_joint'>0 0 0 0 -0 0</pose>
        <inertial>
          <pose>-0.00237 -0.015421 0.031056 0 -0 0</pose>
          <mass>3.87494</mass>
          <inertia>
            <ixx>0.0214096</ixx>
            <ixy>-2.461e-05</ixy>
            <ixz>0.00027172</ixz>
            <iyy>0.0155891</iyy>
            <iyz>0.0018192</iyz>
            <izz>0.0137787</izz>
          </inertia>
        </inertial>
        <collision name='wam/shoulder_pitch_link_collision'>
          <pose>0 0 0 0 -0 0</pose>
          <geometry>
            <mesh>
              <scale>1 1 1</scale>
              <uri>/home/nckmlb/nuws/src/barrett_ros_arms_test/barrett_model/models/sw_meshes/shoulder_pitch_link_convex.dae</uri>
            </mesh>
          </geometry>
          <surface>
            <contact>
              <ode/>
            </contact>
            <bounce/>
            <friction>
              <torsional>
                <ode/>
              </torsional>
              <ode/>
            </friction>
          </surface>
          <max_contacts>10</max_contacts>
        </collision>
        <visual name='wam/shoulder_pitch_link_visual'>
          <pose>0 0 0 0 -0 0</pose>
          <geometry>
            <mesh>
              <scale>1 1 1</scale>
              <uri>/home/nckmlb/nuws/src/barrett_ros_arms_test/barrett_model/models/sw_meshes/shoulder_pitch_link_fine.stl</uri>
            </mesh>
          </geometry>
        </visual>
        <self_collide>0</self_collide>
        <enable_wind>0</enable_wind>
        <kinematic>0</kinematic>
      </link>
      <joint name='wam/shoulder_yaw_joint' type='revolute'>
        <pose relative_to='wam/shoulder_pitch_link'>0 0 0 1.5708 -0 0</pose>
        <parent>wam/shoulder_pitch_link</parent>
        <child>wam/upper_arm_link</child>
        <axis>
          <xyz>0 0 1</xyz>
          <limit>
            <lower>-2.8</lower>
            <upper>2.8</upper>
            <effort>45</effort>
            <velocity>2</velocity>
          </limit>
          <dynamics>
            <damping>1.65</damping>
            <friction>0</friction>
            <spring_reference>0</spring_reference>
            <spring_stiffness>0</spring_stiffness>
          </dynamics>
        </axis>
        <physics>
          <provide_feedback>1</provide_feedback>
          <ode>
            <implicit_spring_damper>1</implicit_spring_damper>
            <cfm_damping>1</cfm_damping>
            <limit>
              <cfm>0</cfm>
              <erp>0.2</erp>
            </limit>
            <provide_feedback>1</provide_feedback>
          </ode>
        </physics>
      </joint>
      <link name='wam/upper_arm_link'>
        <pose relative_to='wam/shoulder_yaw_joint'>0 0 0 0 -0 0</pose>
        <inertial>
          <pose>0.006833 3.3e-05 0.392492 0 -0 0</pose>
          <mass>2.20228</mass>
          <inertia>
            <ixx>0.0591108</ixx>
            <ixy>-7.38e-06</ixy>
            <ixz>-0.00249612</ixz>
            <iyy>0.0592704</iyy>
            <iyz>1.767e-05</iyz>
            <izz>0.0032455</izz>
          </inertia>
        </inertial>
        <collision name='wam/upper_arm_link_collision'>
          <pose>0 0 0 0 -0 0</pose>
          <geometry>
            <mesh>
              <scale>1 1 1</scale>
              <uri>/home/nckmlb/nuws/src/barrett_ros_arms_test/barrett_model/models/sw_meshes/upper_arm_link_convex_decomposition.dae</uri>
            </mesh>
          </geometry>
          <surface>
            <contact>
              <ode/>
            </contact>
            <bounce/>
            <friction>
              <torsional>
                <ode/>
              </torsional>
              <ode/>
            </friction>
          </surface>
          <max_contacts>10</max_contacts>
        </collision>
        <visual name='wam/upper_arm_link_visual'>
          <pose>0 0 0 0 -0 0</pose>
          <geometry>
            <mesh>
              <scale>1 1 1</scale>
              <uri>/home/nckmlb/nuws/src/barrett_ros_arms_test/barrett_model/models/sw_meshes/upper_arm_link_fine.stl</uri>
            </mesh>
          </geometry>
        </visual>
        <self_collide>0</self_collide>
        <enable_wind>0</enable_wind>
        <kinematic>0</kinematic>
      </link>
      <joint name='wam/elbow_pitch_joint' type='revolute'>
        <pose relative_to='wam/upper_arm_link'>0.045 0 0.55 -1.5708 0 0</pose>
        <parent>wam/upper_arm_link</parent>
        <child>wam/forearm_link</child>
        <axis>
          <xyz>0 0 1</xyz>
          <limit>
            <lower>-0.9</lower>
            <upper>3.14159</upper>
            <effort>30</effort>
            <velocity>2</velocity>
          </limit>
          <dynamics>
            <damping>0.88</damping>
            <friction>0</friction>
            <spring_reference>0</spring_reference>
            <spring_stiffness>0</spring_stiffness>
          </dynamics>
        </axis>
        <physics>
          <provide_feedback>1</provide_feedback>
          <ode>
            <implicit_spring_damper>1</implicit_spring_damper>
            <cfm_damping>1</cfm_damping>
            <limit>
              <cfm>0</cfm>
              <erp>0.2</erp>
            </limit>
            <provide_feedback>1</provide_feedback>
          </ode>
        </physics>
      </joint>
      <link name='wam/forearm_link'>
        <pose relative_to='wam/elbow_pitch_joint'>0 0 0 0 -0 0</pose>
        <inertial>
          <pose>-0.040015 -0.142717 -0.000229 0 -0 0</pose>
          <mass>0.500168</mass>
          <inertia>
            <ixx>0.0149167</ixx>
            <ixy>0.00150604</ixy>
            <ixz>1.741e-05</ixz>
            <iyy>0.00294463</iyy>
            <iyz>2.109e-05</iyz>
            <izz>0.0148299</izz>
          </inertia>
        </inertial>
        <collision name='wam/forearm_link_collision'>
          <pose>0 0 0 0 -0 0</pose>
          <geometry>
            <mesh>
              <scale>1 1 1</scale>
              <uri>/home/nckmlb/nuws/src/barrett_ros_arms_test/barrett_model/models/sw_meshes/elbow_link_convex.dae</uri>
            </mesh>
          </geometry>
          <surface>
            <contact>
              <ode/>
            </contact>
            <bounce/>
            <friction>
              <torsional>
                <ode/>
              </torsional>
              <ode/>
            </friction>
          </surface>
          <max_contacts>10</max_contacts>
        </collision>
        <collision name='wam/forearm_link_collision_1'>
          <pose>-0.045 -0.073 0 1.5708 -0 0</pose>
          <geometry>
            <mesh>
              <scale>1 1 1</scale>
              <uri>/home/nckmlb/nuws/src/barrett_ros_arms_test/barrett_model/models/sw_meshes/forearm_link_convex_decomposition.dae</uri>
            </mesh>
          </geometry>
          <surface>
            <contact>
              <ode/>
            </contact>
            <bounce/>
            <friction>
              <torsional>
                <ode/>
              </torsional>
              <ode/>
            </friction>
          </surface>
          <max_contacts>10</max_contacts>
        </collision>
        <visual name='wam/forearm_link_visual'>
          <pose>0 0 0 0 -0 0</pose>
          <geometry>
            <mesh>
              <scale>1 1 1</scale>
              <uri>/home/nckmlb/nuws/src/barrett_ros_arms_test/barrett_model/models/sw_meshes/elbow_link_fine.stl</uri>
            </mesh>
          </geometry>
        </visual>
        <visual name='wam/forearm_link_visual_1'>
          <pose>-0.045 -0.073 0 1.5708 -0 0</pose>
          <geometry>
            <mesh>
              <scale>1 1 1</scale>
              <uri>/home/nckmlb/nuws/src/barrett_ros_arms_test/barrett_model/models/sw_meshes/forearm_link_fine.stl</uri>
            </mesh>
          </geometry>
        </visual>
        <self_collide>0</self_collide>
        <enable_wind>0</enable_wind>
        <kinematic>0</kinematic>
      </link>
      <joint name='wam/wrist_yaw_joint' type='revolute'>
        <pose relative_to='wam/forearm_link'>-0.045 -0.3 0 1.5708 -0 0</pose>
        <parent>wam/forearm_link</parent>
        <child>wam/wrist_yaw_link</child>
        <axis>
          <xyz>0 0 1</xyz>
          <limit>
            <lower>-4.55</lower>
            <upper>1.25</upper>
            <effort>10</effort>
            <velocity>2</velocity>
          </limit>
          <dynamics>
            <damping>0.55</damping>
            <friction>0</friction>
            <spring_reference>0</spring_reference>
            <spring_stiffness>0</spring_stiffness>
          </dynamics>
        </axis>
        <physics>
          <provide_feedback>1</provide_feedback>
          <ode>
            <implicit_spring_damper>1</implicit_spring_damper>
            <cfm_damping>1</cfm_damping>
            <limit>
              <cfm>0</cfm>
              <erp>0.2</erp>
            </limit>
            <provide_feedback>1</provide_feedback>
          </ode>
        </physics>
      </joint>
      <link name='wam/wrist_yaw_link'>
        <pose relative_to='wam/wrist_yaw_joint'>0 0 0 0 -0 0</pose>
        <inertial>
          <pose>8.9e-05 0.004358 -0.005112 0 -0 0</pose>
          <mass>1.05376</mass>
          <inertia>
            <ixx>5.029e-05</ixx>
            <ixy>2e-07</ixy>
            <ixz>7.582e-05</ixz>
            <iyy>7.582e-05</iyy>
            <iyz>-3.59e-06</iyz>
            <izz>6.27e-05</izz>
          </inertia>
        </inertial>
        <collision name='wam/wrist_yaw_link_collision'>
          <pose>0 0 0 0 -0 0</pose>
          <geometry>
            <mesh>
              <scale>1 1 1</scale>
              <uri>/home/nckmlb/nuws/src/barrett_ros_arms_test/barrett_model/models/sw_meshes/wrist_yaw_link_convex_decomposition.dae</uri>
            </mesh>
          </geometry>
          <surface>
            <contact>
              <ode/>
            </contact>
            <bounce/>
            <friction>
              <torsional>
                <ode/>
              </torsional>
              <ode/>
            </friction>
          </surface>
          <max_contacts>10</max_contacts>
        </collision>
        <visual name='wam/wrist_yaw_link_visual'>
          <pose>0 0 0 0 -0 0</pose>
          <geometry>
            <mesh>
              <scale>1 1 1</scale>
              <uri>/home/nckmlb/nuws/src/barrett_ros_arms_test/barrett_model/models/sw_meshes/wrist_yaw_link_fine.stl</uri>
            </mesh>
          </geometry>
        </visual>
        <self_collide>0</self_collide>
        <enable_wind>0</enable_wind>
        <kinematic>0</kinematic>
      </link>
      <joint name='wam/wrist_pitch_joint' type='revolute'>
        <pose relative_to='wam/wrist_yaw_link'>0 0 0 -1.5708 0 0</pose>
        <parent>wam/wrist_yaw_link</parent>
        <child>wam/wrist_pitch_link</child>
        <axis>
          <xyz>0 0 1</xyz>
          <limit>
            <lower>-1.5707</lower>
            <upper>1.5707</upper>
            <effort>10</effort>
            <velocity>2</velocity>
          </limit>
          <dynamics>
            <damping>0.11</damping>
            <friction>0</friction>
            <spring_reference>0</spring_reference>
            <spring_stiffness>0</spring_stiffness>
          </dynamics>
        </axis>
        <physics>
          <provide_feedback>1</provide_feedback>
          <ode>
            <implicit_spring_damper>1</implicit_spring_damper>
            <cfm_damping>1</cfm_damping>
            <limit>
              <cfm>0</cfm>
              <erp>0.2</erp>
            </limit>
            <provide_feedback>1</provide_feedback>
          </ode>
        </physics>
      </joint>
      <link name='wam/wrist_pitch_link'>
        <pose relative_to='wam/wrist_pitch_joint'>0 0 0 0 -0 0</pose>
        <inertial>
          <pose>-0.000123 -0.024683 -0.017032 0 -0 0</pose>
          <mass>0.517974</mass>
          <inertia>
            <ixx>0.00055516</ixx>
            <ixy>6.1e-07</ixy>
            <ixz>-7.4e-07</ixz>
            <iyy>0.00024367</iyy>
            <iyz>-4.59e-05</iyz>
            <izz>0.00045358</izz>
          </inertia>
        </inertial>
        <collision name='wam/wrist_pitch_link_collision'>
          <pose>0 0 0 0 -0 0</pose>
          <geometry>
            <mesh>
              <scale>1 1 1</scale>
              <uri>/home/nckmlb/nuws/src/barrett_ros_arms_test/barrett_model/models/sw_meshes/wrist_pitch_link_convex_decomposition.dae</uri>
            </mesh>
          </geometry>
          <surface>
            <contact>
              <ode/>
            </contact>
            <bounce/>
            <friction>
              <torsional>
                <ode/>
              </torsional>
              <ode/>
            </friction>
          </surface>
          <max_contacts>10</max_contacts>
        </collision>
        <visual name='wam/wrist_pitch_link_visual'>
          <pose>0 0 0 0 -0 0</pose>
          <geometry>
            <mesh>
              <scale>1 1 1</scale>
              <uri>/home/nckmlb/nuws/src/barrett_ros_arms_test/barrett_model/models/sw_meshes/wrist_pitch_link_fine.stl</uri>
            </mesh>
          </geometry>
        </visual>
        <self_collide>0</self_collide>
        <enable_wind>0</enable_wind>
        <kinematic>0</kinematic>
      </link>
      <joint name='wam/palm_yaw_joint' type='revolute'>
        <pose relative_to='wam/wrist_pitch_link'>0 0 0 1.5708 -0 0</pose>
        <parent>wam/wrist_pitch_link</parent>
        <child>wam/wrist_palm_link</child>
        <axis>
          <xyz>0 0 1</xyz>
          <limit>
            <lower>-3</lower>
            <upper>3</upper>
            <effort>10</effort>
            <velocity>2</velocity>
          </limit>
          <dynamics>
            <damping>0.11</damping>
            <friction>0</friction>
            <spring_reference>0</spring_reference>
            <spring_stiffness>0</spring_stiffness>
          </dynamics>
        </axis>
        <physics>
          <provide_feedback>1</provide_feedback>
          <ode>
            <implicit_spring_damper>1</implicit_spring_damper>
            <cfm_damping>1</cfm_damping>
            <limit>
              <cfm>0</cfm>
              <erp>0.2</erp>
            </limit>
            <provide_feedback>1</provide_feedback>
          </ode>
        </physics>
      </joint>
      <link name='wam/wrist_palm_link'>
        <pose relative_to='wam/palm_yaw_joint'>0 0 0 0 -0 0</pose>
        <inertial>
          <pose>-4.4e-05 0.004333 0.090805 0 -0 0</pose>
          <mass>0.588594</mass>
          <inertia>
            <ixx>0.000274516</ixx>
            <ixy>-3.7692e-08</ixy>
            <ixz>-4.18824e-05</ixz>
            <iyy>0.000556622</iyy>
            <iyz>-1.48293e-05</iyz>
            <izz>0.000312871</izz>
          </inertia>
        </inertial>
        <collision name='wam/wrist_palm_link_collision'>
          <pose>0 0 0 0 -0 0</pose>
          <geometry>
            <mesh>
              <scale>1 1 1</scale>
              <uri>/home/nckmlb/nuws/src/barrett_ros_arms_test/barrett_model/models/sw_meshes/wrist_palm_link_convex.dae</uri>
            </mesh>
          </geometry>
          <surface>
            <contact>
              <ode/>
            </contact>
            <bounce/>
            <friction>
              <torsional>
                <ode/>
              </torsional>
              <ode/>
            </friction>
          </surface>
          <max_contacts>10</max_contacts>
        </collision>
        <collision name='wam/wrist_palm_link_fixed_joint_lump__wam/bhand/bhand_palm_link_collision_1'>
          <pose>0 0 0.06 0 -0 0</pose>
          <geometry>
            <mesh>
              <scale>1 1 1</scale>
              <uri>/home/nckmlb/nuws/src/barrett_ros_arms_test/barrett_model/models/sw_meshes/bhand/bhand_palm_link_convex_decomposition.dae</uri>
            </mesh>
          </geometry>
          <surface>
            <contact>
              <ode/>
            </contact>
            <friction>
              <ode>
                <mu>0.8</mu>
                <mu2>0.8</mu2>
              </ode>
              <torsional>
                <ode/>
              </torsional>
            </friction>
            <bounce/>
          </surface>
          <max_contacts>10</max_contacts>
        </collision>
        <visual name='wam/wrist_palm_link_visual'>
          <pose>0 0 0 0 -0 0</pose>
          <geometry>
            <mesh>
              <scale>1 1 1</scale>
              <uri>/home/nckmlb/nuws/src/barrett_ros_arms_test/barrett_model/models/sw_meshes/wrist_palm_link_fine.stl</uri>
            </mesh>
          </geometry>
        </visual>
        <visual name='wam/wrist_palm_link_fixed_joint_lump__wam/bhand/bhand_palm_link_visual_1'>
          <pose>0 0 0.06 0 -0 0</pose>
          <geometry>
            <mesh>
              <scale>1 1 1</scale>
              <uri>/home/nckmlb/nuws/src/barrett_ros_arms_test/barrett_model/models/sw_meshes/bhand/bhand_palm_fine.stl</uri>
            </mesh>
          </geometry>
        </visual>
        <gravity>1</gravity>
        <velocity_decay/>
        <self_collide>0</self_collide>
        <enable_wind>0</enable_wind>
        <kinematic>0</kinematic>
      </link>
      <joint name='wam/bhand/finger_1/prox_joint' type='revolute'>
        <pose relative_to='wam/wrist_palm_link'>-0.025 0 0.1015 0 0 -1.5708</pose>
        <parent>wam/wrist_palm_link</parent>
        <child>wam/bhand/finger_1/prox_link</child>
        <axis>
          <xyz>0 0 -1</xyz>
          <limit>
            <lower>0</lower>
            <upper>3.14159</upper>
            <effort>5</effort>
            <velocity>5</velocity>
          </limit>
          <dynamics>
            <damping>0.11</damping>
            <friction>0</friction>
            <spring_reference>0</spring_reference>
            <spring_stiffness>0</spring_stiffness>
          </dynamics>
        </axis>
        <physics>
          <provide_feedback>1</provide_feedback>
          <ode>
            <implicit_spring_damper>1</implicit_spring_damper>
            <cfm_damping>1</cfm_damping>
            <limit>
              <cfm>0</cfm>
              <erp>0.2</erp>
            </limit>
            <provide_feedback>1</provide_feedback>
          </ode>
        </physics>
      </joint>
      <link name='wam/bhand/finger_1/prox_link'>
        <pose relative_to='wam/bhand/finger_1/prox_joint'>0 0 0 0 -0 0</pose>
        <inertial>
          <pose>0.023133 0.000786 0.000528 0 -0 0</pose>
          <mass>0.14109</mass>
          <inertia>
            <ixx>4.872e-06</ixx>
            <ixy>1.7103e-06</ixy>
            <ixz>3.4041e-08</ixz>
            <iyy>7.6588e-05</iyy>
            <iyz>2.3133e-08</iyz>
            <izz>7.7733e-05</izz>
          </inertia>
        </inertial>
        <collision name='wam/bhand/finger_1/prox_link_collision'>
          <pose>0 0 0 0 -0 0</pose>
          <geometry>
            <mesh>
              <scale>1 1 1</scale>
              <uri>/home/nckmlb/nuws/src/barrett_ros_arms_test/barrett_model/models/sw_meshes/bhand/bhand_finger_prox_link_convex_decomposition.dae</uri>
            </mesh>
          </geometry>
          <surface>
            <contact>
              <ode/>
            </contact>
            <friction>
              <ode>
                <mu>0.8</mu>
                <mu2>0.8</mu2>
              </ode>
              <torsional>
                <ode/>
              </torsional>
            </friction>
            <bounce/>
          </surface>
          <max_contacts>10</max_contacts>
        </collision>
        <visual name='wam/bhand/finger_1/prox_link_visual'>
          <pose>0 0 0 0 -0 0</pose>
          <geometry>
            <mesh>
              <scale>1 1 1</scale>
              <uri>/home/nckmlb/nuws/src/barrett_ros_arms_test/barrett_model/models/sw_meshes/bhand/bhand_finger_prox_link_fine.stl</uri>
            </mesh>
          </geometry>
        </visual>
        <gravity>1</gravity>
        <velocity_decay/>
        <self_collide>0</self_collide>
        <enable_wind>0</enable_wind>
        <kinematic>0</kinematic>
      </link>
      <joint name='wam/bhand/finger_1/med_joint' type='revolute'>
        <pose relative_to='wam/bhand/finger_1/prox_link'>0.05 0 0.0339 1.5708 -0 0</pose>
        <parent>wam/bhand/finger_1/prox_link</parent>
        <child>wam/bhand/finger_1/med_link</child>
        <axis>
          <xyz>0 0 1</xyz>
          <limit>
            <lower>0</lower>
            <upper>2.44346</upper>
            <effort>5</effort>
            <velocity>5</velocity>
          </limit>
          <dynamics>
            <damping>0.11</damping>
            <friction>0</friction>
            <spring_reference>0</spring_reference>
            <spring_stiffness>0</spring_stiffness>
          </dynamics>
        </axis>
        <physics>
          <provide_feedback>1</provide_feedback>
          <ode>
            <implicit_spring_damper>1</implicit_spring_damper>
            <cfm_damping>1</cfm_damping>
            <limit>
              <cfm>0</cfm>
              <erp>0.2</erp>
            </limit>
            <provide_feedback>1</provide_feedback>
          </ode>
        </physics>
      </joint>
      <link name='wam/bhand/finger_1/med_link'>
        <pose relative_to='wam/bhand/finger_1/med_joint'>0 0 0 0 -0 0</pose>
        <inertial>
          <pose>0.023133 0.000786 0.000528 0 -0 0</pose>
          <mass>0.062139</mass>
          <inertia>
            <ixx>4.872e-06</ixx>
            <ixy>1.7103e-06</ixy>
            <ixz>3.4041e-08</ixz>
            <iyy>7.6588e-05</iyy>
            <iyz>2.3133e-08</iyz>
            <izz>7.7733e-05</izz>
          </inertia>
        </inertial>
        <collision name='wam/bhand/finger_1/med_link_collision'>
          <pose>0 0 0 0 -0 0</pose>
          <geometry>
            <mesh>
              <scale>1 1 1</scale>
              <uri>/home/nckmlb/nuws/src/barrett_ros_arms_test/barrett_model/models/sw_meshes/bhand/bhand_finger_med_link_convex.dae</uri>
            </mesh>
          </geometry>
          <surface>
            <contact>
              <ode/>
            </contact>
            <friction>
              <ode>
                <mu>0.8</mu>
                <mu2>0.8</mu2>
              </ode>
              <torsional>
                <ode/>
              </torsional>
            </friction>
            <bounce/>
          </surface>
          <max_contacts>10</max_contacts>
        </collision>
        <visual name='wam/bhand/finger_1/med_link_visual'>
          <pose>0 0 0 0 -0 0</pose>
          <geometry>
            <mesh>
              <scale>1 1 1</scale>
              <uri>/home/nckmlb/nuws/src/barrett_ros_arms_test/barrett_model/models/sw_meshes/bhand/bhand_finger_med_link_fine.stl</uri>
            </mesh>
          </geometry>
        </visual>
        <gravity>1</gravity>
        <velocity_decay/>
        <self_collide>0</self_collide>
        <enable_wind>0</enable_wind>
        <kinematic>0</kinematic>
      </link>
      <joint name='wam/bhand/finger_1/dist_joint' type='revolute'>
        <pose relative_to='wam/bhand/finger_1/med_link'>0.06994 0.003 0 0 -0 0.785398</pose>
        <parent>wam/bhand/finger_1/med_link</parent>
        <child>wam/bhand/finger_1/dist_link</child>
        <axis>
          <xyz>0 0 1</xyz>
          <limit>
            <lower>0</lower>
            <upper>0.837758</upper>
            <effort>5</effort>
            <velocity>5</velocity>
          </limit>
          <dynamics>
            <damping>0.11</damping>
            <friction>0</friction>
            <spring_reference>0</spring_reference>
            <spring_stiffness>0</spring_stiffness>
          </dynamics>
        </axis>
        <physics>
          <provide_feedback>1</provide_feedback>
          <ode>
            <implicit_spring_damper>1</implicit_spring_damper>
            <cfm_damping>1</cfm_damping>
            <limit>
              <cfm>0</cfm>
              <erp>0.2</erp>
            </limit>
            <provide_feedback>1</provide_feedback>
          </ode>
        </physics>
      </joint>
      <link name='wam/bhand/finger_1/dist_link'>
        <pose relative_to='wam/bhand/finger_1/dist_joint'>0 0 0 0 -0 0</pose>
        <inertial>
          <pose>0.022826 0.001049 0.00042 0 -0 0</pose>
          <mass>0.041378</mass>
          <inertia>
            <ixx>4.1582e-06</ixx>
            <ixy>1.43083e-06</ixy>
            <ixz>1.01071e-07</ixz>
            <iyy>3.93767e-05</iyy>
            <iyz>-4.40926e-13</iyz>
            <izz>3.82757e-05</izz>
          </inertia>
        </inertial>
        <collision name='wam/bhand/finger_1/dist_link_collision'>
          <pose>0 0 0 0 0 -0.785398</pose>
          <geometry>
            <mesh>
              <scale>1 1 1</scale>
              <uri>/home/nckmlb/nuws/src/barrett_ros_arms_test/barrett_model/models/sw_meshes/bhand/bhand_finger_dist_link_convex.dae</uri>
            </mesh>
          </geometry>
          <surface>
            <contact>
              <ode/>
            </contact>
            <friction>
              <ode>
                <mu>0.8</mu>
                <mu2>0.8</mu2>
              </ode>
              <torsional>
                <ode/>
              </torsional>
            </friction>
            <bounce/>
          </surface>
          <max_contacts>10</max_contacts>
        </collision>
        <visual name='wam/bhand/finger_1/dist_link_visual'>
          <pose>0 0 0 0 0 -0.785398</pose>
          <geometry>
            <mesh>
              <scale>1 1 1</scale>
              <uri>/home/nckmlb/nuws/src/barrett_ros_arms_test/barrett_model/models/sw_meshes/bhand/bhand_finger_dist_link_fine.stl</uri>
            </mesh>
          </geometry>
        </visual>
        <gravity>1</gravity>
        <velocity_decay/>
        <self_collide>1</self_collide>
        <enable_wind>0</enable_wind>
        <kinematic>0</kinematic>
      </link>
      <joint name='wam/bhand/finger_2/prox_joint' type='revolute'>
        <pose relative_to='wam/wrist_palm_link'>0.025 0 0.1015 0 0 -1.5708</pose>
        <parent>wam/wrist_palm_link</parent>
        <child>wam/bhand/finger_2/prox_link</child>
        <axis>
          <xyz>0 0 1</xyz>
          <limit>
            <lower>0</lower>
            <upper>3.14159</upper>
            <effort>5</effort>
            <velocity>5</velocity>
          </limit>
          <dynamics>
            <damping>0.11</damping>
            <friction>0</friction>
            <spring_reference>0</spring_reference>
            <spring_stiffness>0</spring_stiffness>
          </dynamics>
        </axis>
        <physics>
          <provide_feedback>1</provide_feedback>
          <ode>
            <implicit_spring_damper>1</implicit_spring_damper>
            <cfm_damping>1</cfm_damping>
            <limit>
              <cfm>0</cfm>
              <erp>0.2</erp>
            </limit>
            <provide_feedback>1</provide_feedback>
          </ode>
        </physics>
      </joint>
      <link name='wam/bhand/finger_2/prox_link'>
        <pose relative_to='wam/bhand/finger_2/prox_joint'>0 0 0 0 -0 0</pose>
        <inertial>
          <pose>0.023133 0.000786 0.000528 0 -0 0</pose>
          <mass>0.14109</mass>
          <inertia>
            <ixx>4.872e-06</ixx>
            <ixy>1.7103e-06</ixy>
            <ixz>3.4041e-08</ixz>
            <iyy>7.6588e-05</iyy>
            <iyz>2.3133e-08</iyz>
            <izz>7.7733e-05</izz>
          </inertia>
        </inertial>
        <collision name='wam/bhand/finger_2/prox_link_collision'>
          <pose>0 0 0 0 -0 0</pose>
          <geometry>
            <mesh>
              <scale>1 1 1</scale>
              <uri>/home/nckmlb/nuws/src/barrett_ros_arms_test/barrett_model/models/sw_meshes/bhand/bhand_finger_prox_link_convex_decomposition.dae</uri>
            </mesh>
          </geometry>
          <surface>
            <contact>
              <ode/>
            </contact>
            <friction>
              <ode>
                <mu>0.8</mu>
                <mu2>0.8</mu2>
              </ode>
              <torsional>
                <ode/>
              </torsional>
            </friction>
            <bounce/>
          </surface>
          <max_contacts>10</max_contacts>
        </collision>
        <visual name='wam/bhand/finger_2/prox_link_visual'>
          <pose>0 0 0 0 -0 0</pose>
          <geometry>
            <mesh>
              <scale>1 1 1</scale>
              <uri>/home/nckmlb/nuws/src/barrett_ros_arms_test/barrett_model/models/sw_meshes/bhand/bhand_finger_prox_link_fine.stl</uri>
            </mesh>
          </geometry>
        </visual>
        <gravity>1</gravity>
        <velocity_decay/>
        <self_collide>0</self_collide>
        <enable_wind>0</enable_wind>
        <kinematic>0</kinematic>
      </link>
      <joint name='wam/bhand/finger_2/med_joint' type='revolute'>
        <pose relative_to='wam/bhand/finger_2/prox_link'>0.05 0 0.0339 1.5708 -0 0</pose>
        <parent>wam/bhand/finger_2/prox_link</parent>
        <child>wam/bhand/finger_2/med_link</child>
        <axis>
          <xyz>0 0 1</xyz>
          <limit>
            <lower>0</lower>
            <upper>2.44346</upper>
            <effort>5</effort>
            <velocity>5</velocity>
          </limit>
          <dynamics>
            <damping>0.11</damping>
            <friction>0</friction>
            <spring_reference>0</spring_reference>
            <spring_stiffness>0</spring_stiffness>
          </dynamics>
        </axis>
        <physics>
          <provide_feedback>1</provide_feedback>
          <ode>
            <implicit_spring_damper>1</implicit_spring_damper>
            <cfm_damping>1</cfm_damping>
            <limit>
              <cfm>0</cfm>
              <erp>0.2</erp>
            </limit>
            <provide_feedback>1</provide_feedback>
          </ode>
        </physics>
      </joint>
      <link name='wam/bhand/finger_2/med_link'>
        <pose relative_to='wam/bhand/finger_2/med_joint'>0 0 0 0 -0 0</pose>
        <inertial>
          <pose>0.023133 0.000786 0.000528 0 -0 0</pose>
          <mass>0.062139</mass>
          <inertia>
            <ixx>4.872e-06</ixx>
            <ixy>1.7103e-06</ixy>
            <ixz>3.4041e-08</ixz>
            <iyy>7.6588e-05</iyy>
            <iyz>2.3133e-08</iyz>
            <izz>7.7733e-05</izz>
          </inertia>
        </inertial>
        <collision name='wam/bhand/finger_2/med_link_collision'>
          <pose>0 0 0 0 -0 0</pose>
          <geometry>
            <mesh>
              <scale>1 1 1</scale>
              <uri>/home/nckmlb/nuws/src/barrett_ros_arms_test/barrett_model/models/sw_meshes/bhand/bhand_finger_med_link_convex.dae</uri>
            </mesh>
          </geometry>
          <surface>
            <contact>
              <ode/>
            </contact>
            <friction>
              <ode>
                <mu>0.8</mu>
                <mu2>0.8</mu2>
              </ode>
              <torsional>
                <ode/>
              </torsional>
            </friction>
            <bounce/>
          </surface>
          <max_contacts>10</max_contacts>
        </collision>
        <visual name='wam/bhand/finger_2/med_link_visual'>
          <pose>0 0 0 0 -0 0</pose>
          <geometry>
            <mesh>
              <scale>1 1 1</scale>
              <uri>/home/nckmlb/nuws/src/barrett_ros_arms_test/barrett_model/models/sw_meshes/bhand/bhand_finger_med_link_fine.stl</uri>
            </mesh>
          </geometry>
        </visual>
        <gravity>1</gravity>
        <velocity_decay/>
        <self_collide>0</self_collide>
        <enable_wind>0</enable_wind>
        <kinematic>0</kinematic>
      </link>
      <joint name='wam/bhand/finger_2/dist_joint' type='revolute'>
        <pose relative_to='wam/bhand/finger_2/med_link'>0.06994 0.003 0 0 -0 0.785398</pose>
        <parent>wam/bhand/finger_2/med_link</parent>
        <child>wam/bhand/finger_2/dist_link</child>
        <axis>
          <xyz>0 0 1</xyz>
          <limit>
            <lower>0</lower>
            <upper>0.837758</upper>
            <effort>5</effort>
            <velocity>5</velocity>
          </limit>
          <dynamics>
            <damping>0.11</damping>
            <friction>0</friction>
            <spring_reference>0</spring_reference>
            <spring_stiffness>0</spring_stiffness>
          </dynamics>
        </axis>
        <physics>
          <provide_feedback>1</provide_feedback>
          <ode>
            <implicit_spring_damper>1</implicit_spring_damper>
            <cfm_damping>1</cfm_damping>
            <limit>
              <cfm>0</cfm>
              <erp>0.2</erp>
            </limit>
            <provide_feedback>1</provide_feedback>
          </ode>
        </physics>
      </joint>
      <link name='wam/bhand/finger_2/dist_link'>
        <pose relative_to='wam/bhand/finger_2/dist_joint'>0 0 0 0 -0 0</pose>
        <inertial>
          <pose>0.022826 0.001049 0.00042 0 -0 0</pose>
          <mass>0.041378</mass>
          <inertia>
            <ixx>4.1582e-06</ixx>
            <ixy>1.43083e-06</ixy>
            <ixz>1.01071e-07</ixz>
            <iyy>3.93767e-05</iyy>
            <iyz>-4.40926e-13</iyz>
            <izz>3.82757e-05</izz>
          </inertia>
        </inertial>
        <collision name='wam/bhand/finger_2/dist_link_collision'>
          <pose>0 0 0 0 0 -0.785398</pose>
          <geometry>
            <mesh>
              <scale>1 1 1</scale>
              <uri>/home/nckmlb/nuws/src/barrett_ros_arms_test/barrett_model/models/sw_meshes/bhand/bhand_finger_dist_link_convex.dae</uri>
            </mesh>
          </geometry>
          <surface>
            <contact>
              <ode/>
            </contact>
            <friction>
              <ode>
                <mu>0.8</mu>
                <mu2>0.8</mu2>
              </ode>
              <torsional>
                <ode/>
              </torsional>
            </friction>
            <bounce/>
          </surface>
          <max_contacts>10</max_contacts>
        </collision>
        <visual name='wam/bhand/finger_2/dist_link_visual'>
          <pose>0 0 0 0 0 -0.785398</pose>
          <geometry>
            <mesh>
              <scale>1 1 1</scale>
              <uri>/home/nckmlb/nuws/src/barrett_ros_arms_test/barrett_model/models/sw_meshes/bhand/bhand_finger_dist_link_fine.stl</uri>
            </mesh>
          </geometry>
        </visual>
        <gravity>1</gravity>
        <velocity_decay/>
        <self_collide>1</self_collide>
        <enable_wind>0</enable_wind>
        <kinematic>0</kinematic>
      </link>
      <joint name='wam/bhand/finger_3/med_joint' type='revolute'>
        <pose relative_to='wam/wrist_palm_link'>0 0.05 0.1354 1.5708 -0 1.5708</pose>
        <parent>wam/wrist_palm_link</parent>
        <child>wam/bhand/finger_3/med_link</child>
        <axis>
          <xyz>0 0 1</xyz>
          <limit>
            <lower>0</lower>
            <upper>2.44346</upper>
            <effort>5</effort>
            <velocity>5</velocity>
          </limit>
          <dynamics>
            <damping>0.11</damping>
            <friction>0</friction>
            <spring_reference>0</spring_reference>
            <spring_stiffness>0</spring_stiffness>
          </dynamics>
        </axis>
        <physics>
          <provide_feedback>1</provide_feedback>
          <ode>
            <implicit_spring_damper>1</implicit_spring_damper>
            <cfm_damping>1</cfm_damping>
            <limit>
              <cfm>0</cfm>
              <erp>0.2</erp>
            </limit>
            <provide_feedback>1</provide_feedback>
          </ode>
        </physics>
      </joint>
      <link name='wam/bhand/finger_3/med_link'>
        <pose relative_to='wam/bhand/finger_3/med_joint'>0 0 0 0 -0 0</pose>
        <inertial>
          <pose>0.023133 0.000786 0.000528 0 -0 0</pose>
          <mass>0.062139</mass>
          <inertia>
            <ixx>4.872e-06</ixx>
            <ixy>1.7103e-06</ixy>
            <ixz>3.4041e-08</ixz>
            <iyy>7.6588e-05</iyy>
            <iyz>2.3133e-08</iyz>
            <izz>7.7733e-05</izz>
          </inertia>
        </inertial>
        <collision name='wam/bhand/finger_3/med_link_collision'>
          <pose>0 0 0 0 -0 0</pose>
          <geometry>
            <mesh>
              <scale>1 1 1</scale>
              <uri>/home/nckmlb/nuws/src/barrett_ros_arms_test/barrett_model/models/sw_meshes/bhand/bhand_finger_med_link_convex.dae</uri>
            </mesh>
          </geometry>
          <surface>
            <contact>
              <ode/>
            </contact>
            <friction>
              <ode>
                <mu>0.8</mu>
                <mu2>0.8</mu2>
              </ode>
              <torsional>
                <ode/>
              </torsional>
            </friction>
            <bounce/>
          </surface>
          <max_contacts>10</max_contacts>
        </collision>
        <visual name='wam/bhand/finger_3/med_link_visual'>
          <pose>0 0 0 0 -0 0</pose>
          <geometry>
            <mesh>
              <scale>1 1 1</scale>
              <uri>/home/nckmlb/nuws/src/barrett_ros_arms_test/barrett_model/models/sw_meshes/bhand/bhand_finger_med_link_fine.stl</uri>
            </mesh>
          </geometry>
        </visual>
        <gravity>1</gravity>
        <velocity_decay/>
        <self_collide>0</self_collide>
        <enable_wind>0</enable_wind>
        <kinematic>0</kinematic>
      </link>
      <joint name='wam/bhand/finger_3/dist_joint' type='revolute'>
        <pose relative_to='wam/bhand/finger_3/med_link'>0.06994 0.003 0 0 -0 0.785398</pose>
        <parent>wam/bhand/finger_3/med_link</parent>
        <child>wam/bhand/finger_3/dist_link</child>
        <axis>
          <xyz>0 0 1</xyz>
          <limit>
            <lower>0</lower>
            <upper>0.837758</upper>
            <effort>5</effort>
            <velocity>5</velocity>
          </limit>
          <dynamics>
            <damping>0.11</damping>
            <friction>0</friction>
            <spring_reference>0</spring_reference>
            <spring_stiffness>0</spring_stiffness>
          </dynamics>
        </axis>
        <physics>
          <provide_feedback>1</provide_feedback>
          <ode>
            <implicit_spring_damper>1</implicit_spring_damper>
            <cfm_damping>1</cfm_damping>
            <limit>
              <cfm>0</cfm>
              <erp>0.2</erp>
            </limit>
            <provide_feedback>1</provide_feedback>
          </ode>
        </physics>
      </joint>
      <link name='wam/bhand/finger_3/dist_link'>
        <pose relative_to='wam/bhand/finger_3/dist_joint'>0 0 0 0 -0 0</pose>
        <inertial>
          <pose>0.022826 0.001049 0.00042 0 -0 0</pose>
          <mass>0.041378</mass>
          <inertia>
            <ixx>4.1582e-06</ixx>
            <ixy>1.43083e-06</ixy>
            <ixz>1.01071e-07</ixz>
            <iyy>3.93767e-05</iyy>
            <iyz>-4.40926e-13</iyz>
            <izz>3.82757e-05</izz>
          </inertia>
        </inertial>
        <collision name='wam/bhand/finger_3/dist_link_collision'>
          <pose>0 0 0 0 0 -0.785398</pose>
          <geometry>
            <mesh>
              <scale>1 1 1</scale>
              <uri>/home/nckmlb/nuws/src/barrett_ros_arms_test/barrett_model/models/sw_meshes/bhand/bhand_finger_dist_link_convex.dae</uri>
            </mesh>
          </geometry>
          <surface>
            <contact>
              <ode/>
            </contact>
            <friction>
              <ode>
                <mu>0.8</mu>
                <mu2>0.8</mu2>
              </ode>
              <torsional>
                <ode/>
              </torsional>
            </friction>
            <bounce/>
          </surface>
          <max_contacts>10</max_contacts>
        </collision>
        <visual name='wam/bhand/finger_3/dist_link_visual'>
          <pose>0 0 0 0 0 -0.785398</pose>
          <geometry>
            <mesh>
              <scale>1 1 1</scale>
              <uri>/home/nckmlb/nuws/src/barrett_ros_arms_test/barrett_model/models/sw_meshes/bhand/bhand_finger_dist_link_fine.stl</uri>
            </mesh>
          </geometry>
        </visual>
        <gravity>1</gravity>
        <velocity_decay/>
        <self_collide>1</self_collide>
        <enable_wind>0</enable_wind>
        <kinematic>0</kinematic>
      </link>
      <pose>0 0 -1 0 -0 0</pose>
    </model>
  </world>
</sdf>
